<?xml version="1.0" encoding="UTF-8"?>
<testsuite name="dashboard_granos-20240502182235" tests="1" file=".py" time="40.022" timestamp="2024-05-02T18:23:15" failures="0" errors="1" skipped="0">
	<testcase classname="dashboard_granos" name="test_dashboard_grain" time="40.022" timestamp="2024-05-02T18:23:15" file="DashboarGranos.py" line="23">
		<error type="TimeoutException" message="Message: 
"><![CDATA[Traceback (most recent call last):
  File "c:\Users\luist\repos\Automatizaciones-SILOHUB-\DashboarGranos.py", line 53, in test_dashboard_grain
    calendar_todate(self.driver, select_data_day, popup_calendar1)
  File "c:\Users\luist\repos\Automatizaciones-SILOHUB-\Elements.py", line 1373, in calendar_todate
    popup_calendario = WebDriverWait(driver, 10).until(
  File "C:\Users\luist\AppData\Roaming\Python\Python310\site-packages\selenium\webdriver\support\wait.py", line 105, in until
    raise TimeoutException(message, screen, stacktrace)
selenium.common.exceptions.TimeoutException: Message: 

]]></error>
	</testcase>
</testsuite>
