<?xml version="1.0" encoding="UTF-8"?>
<testsuite name="Onboarding_test_tenant-20231219113419" tests="1" file=".py" time="158.123" timestamp="2023-12-19T11:36:57" failures="0" errors="1" skipped="0">
	<testcase classname="Onboarding_test_tenant" name="test_tenat_onboarding" time="158.123" timestamp="2023-12-19T11:36:57" file="Onboarding.py" line="36">
		<error type="ProtocolError" message="('Connection aborted.', ConnectionResetError(10054, 'Se ha forzado la interrupción de una conexión existente por el host remoto', None, 10054, None))"><![CDATA[Traceback (most recent call last):
  File "C:\Users\luist\AppData\Roaming\Python\Python310\site-packages\urllib3\connectionpool.py", line 703, in urlopen
    httplib_response = self._make_request(
  File "C:\Users\luist\AppData\Roaming\Python\Python310\site-packages\urllib3\connectionpool.py", line 449, in _make_request
    six.raise_from(e, None)
  File "<string>", line 3, in raise_from
  File "C:\Users\luist\AppData\Roaming\Python\Python310\site-packages\urllib3\connectionpool.py", line 444, in _make_request
    httplib_response = conn.getresponse()
  File "C:\Program Files\Python310\lib\http\client.py", line 1374, in getresponse
    response.begin()
  File "C:\Program Files\Python310\lib\http\client.py", line 318, in begin
    version, status, reason = self._read_status()
  File "C:\Program Files\Python310\lib\http\client.py", line 279, in _read_status
    line = str(self.fp.readline(_MAXLINE + 1), "iso-8859-1")
  File "C:\Program Files\Python310\lib\socket.py", line 705, in readinto
    return self._sock.recv_into(b)
ConnectionResetError: [WinError 10054] Se ha forzado la interrupción de una conexión existente por el host remoto

During handling of the above exception, another exception occurred:

Traceback (most recent call last):
  File "c:\Users\luist\repos\Automatizaciones-SILOHUB-\Onboarding.py", line 106, in test_tenat_onboarding
    cuit = CUITGenerator.generate_random_cuit(self.driver)
  File "c:\Users\luist\repos\Automatizaciones-SILOHUB-\GeneradorCuit.py", line 20, in generate_random_cuit
    input_element.send_keys(Keys.ENTER)
  File "C:\Users\luist\AppData\Roaming\Python\Python310\site-packages\selenium\webdriver\remote\webelement.py", line 230, in send_keys
    self._execute(
  File "C:\Users\luist\AppData\Roaming\Python\Python310\site-packages\selenium\webdriver\remote\webelement.py", line 394, in _execute
    return self._parent.execute(command, params)
  File "C:\Users\luist\AppData\Roaming\Python\Python310\site-packages\selenium\webdriver\remote\webdriver.py", line 345, in execute
    response = self.command_executor.execute(driver_command, params)
  File "C:\Users\luist\AppData\Roaming\Python\Python310\site-packages\selenium\webdriver\remote\remote_connection.py", line 300, in execute
    return self._request(command_info[0], url, body=data)
  File "C:\Users\luist\AppData\Roaming\Python\Python310\site-packages\selenium\webdriver\remote\remote_connection.py", line 321, in _request
    response = self._conn.request(method, url, body=body, headers=headers)
  File "C:\Users\luist\AppData\Roaming\Python\Python310\site-packages\urllib3\request.py", line 78, in request
    return self.request_encode_body(
  File "C:\Users\luist\AppData\Roaming\Python\Python310\site-packages\urllib3\request.py", line 170, in request_encode_body
    return self.urlopen(method, url, **extra_kw)
  File "C:\Users\luist\AppData\Roaming\Python\Python310\site-packages\urllib3\poolmanager.py", line 376, in urlopen
    response = conn.urlopen(method, u.request_uri, **kw)
  File "C:\Users\luist\AppData\Roaming\Python\Python310\site-packages\urllib3\connectionpool.py", line 785, in urlopen
    retries = retries.increment(
  File "C:\Users\luist\AppData\Roaming\Python\Python310\site-packages\urllib3\util\retry.py", line 550, in increment
    raise six.reraise(type(error), error, _stacktrace)
  File "C:\Users\luist\AppData\Roaming\Python\Python310\site-packages\urllib3\packages\six.py", line 769, in reraise
    raise value.with_traceback(tb)
  File "C:\Users\luist\AppData\Roaming\Python\Python310\site-packages\urllib3\connectionpool.py", line 703, in urlopen
    httplib_response = self._make_request(
  File "C:\Users\luist\AppData\Roaming\Python\Python310\site-packages\urllib3\connectionpool.py", line 449, in _make_request
    six.raise_from(e, None)
  File "<string>", line 3, in raise_from
  File "C:\Users\luist\AppData\Roaming\Python\Python310\site-packages\urllib3\connectionpool.py", line 444, in _make_request
    httplib_response = conn.getresponse()
  File "C:\Program Files\Python310\lib\http\client.py", line 1374, in getresponse
    response.begin()
  File "C:\Program Files\Python310\lib\http\client.py", line 318, in begin
    version, status, reason = self._read_status()
  File "C:\Program Files\Python310\lib\http\client.py", line 279, in _read_status
    line = str(self.fp.readline(_MAXLINE + 1), "iso-8859-1")
  File "C:\Program Files\Python310\lib\socket.py", line 705, in readinto
    return self._sock.recv_into(b)
urllib3.exceptions.ProtocolError: ('Connection aborted.', ConnectionResetError(10054, 'Se ha forzado la interrupción de una conexión existente por el host remoto', None, 10054, None))
]]></error>
		<system-out><![CDATA[El texto obtenido es: DOCUMENTACIÓN
El texto obtenido es: Para poder continuar al siguiente paso, será obligatorio completar los campos que se muestran a continuación.
]]></system-out>
	</testcase>
</testsuite>
