<?xml version="1.0" encoding="UTF-8"?>
<testsuite name="EntregasAplicadas.cta_entregasAplicadas-failed" tests="1" file="EntregasAplicadas.py" time="71.606" timestamp="2024-05-17T11:57:45" failures="1" errors="0" skipped="0">
	<testcase classname="EntregasAplicadas.cta_entregasAplicadas" name="test_delivery_applied" time="71.606" timestamp="2024-05-17T11:57:45" file="EntregasAplicadas.py" line="22">
		<failure type="AssertionError" message=""><![CDATA[Traceback (most recent call last):
  File "c:\Users\luist\repos\Automatizaciones-SILOHUB-\EntregasAplicadas.py", line 155, in test_delivery_applied
    validate_text_visible(self.driver, number_TK, number_TK_expected )
  File "c:\Users\luist\repos\Automatizaciones-SILOHUB-\Elements.py", line 1145, in validate_text_visible
    assert text_obtained == text_expected
AssertionError
]]></failure>
		<system-out><![CDATA[El texto encontrado es  MIS ENTREGAS
¡Elemento encontrado y clickeado 2 veces con éxito!
¡Elemento encontrado y clickeado 3 veces con éxito!
¡Elemento encontrado y clickeado 1 veces con éxito!
El texto no coincide con los valores esperados. Texto actual: '192.500,60'
El texto no coincide con los valores esperados. Texto actual: '187.237,45'
El texto es visible para el usuario
]]></system-out>
	</testcase>
</testsuite>
